Workbook
Name Slicer_Discount_Category: #N/A
Name Slicer_PRICE_Category: #N/A
Name Slicer_Rating_Category: #N/A

Sheet Cleaned Jumia Data
A1: Product | B1: Current price | C1: PRICE Category | D1: Old Price | E1: Discount Amount | F1: Discount | G1: Ratings | H1: Review | I1: Rating Category | J1: Discount Category
A2: 115 Piece Set Of Multifunctional Precision Screwdrivers | B2: 950 | C2: =IF(B2<=1000, "0 - 1000", IF(B2 <=2000,"1000 - 2000", IF(B2<=4000,"2000 - 4000", "Above 400"))) -> 0 - 1000 | D2: 1525 | E2: =D2-B2 -> 575 | F2: 0.38 | G2: 4.5 | H2: 2 | I2: =IF(G2<3,"Poor", IF(G2>=4.5,"Excelent","Average")) -> Excelent | J2: {=_xlfn.IFS(F2<=0.2,"Low Discount",F2<=0.4,"Medium Discount",F2>0.4,"High Discount")} -> Medium Discount
A3: Metal Decorative Hooks Key Hangers Entryway Wall Hooks Towel Hooks - Home | B3: 527 | C3: =IF(B3<=1000, "0 - 1000", IF(B3 <=2000,"1000 - 2000", IF(B3<=4000,"2000 - 4000", "Above 400"))) -> 0 - 1000 | D3: 999 | E3: =D3-B3 -> 472 | F3: 0.47 | G3: 4.1 | H3: 14 | I3: =IF(G3<3,"Poor", IF(G3>=4.5,"Excelent","Average")) -> Average | J3: {=_xlfn.IFS(F3<=0.2,"Low Discount",F3<=0.4,"Medium Discount",F3>0.4,"High Discount")} -> High Discount
A4: Portable Mini Cordless Car Vacuum Cleaner - Blue | B4: 2199 | C4: =IF(B4<=1000, "0 - 1000", IF(B4 <=2000,"1000 - 2000", IF(B4<=4000,"2000 - 4000", "Above 400"))) -> 2000 - 4000 | D4: 2923 | E4: =D4-B4 -> 724 | F4: 0.25 | G4: 4.6 | H4: 24 | I4: =IF(G4<3,"Poor", IF(G4>=4.5,"Excelent","Average")) -> Excelent | J4: {=_xlfn.IFS(F4<=0.2,"Low Discount",F4<=0.4,"Medium Discount",F4>0.4,"High Discount")} -> Medium Discount
A5: Weighing Scale Digital Bathroom Body Fat Scale USB-Black | B5: 1580 | C5: =IF(B5<=1000, "0 - 1000", IF(B5 <=2000,"1000 - 2000", IF(B5<=4000,"2000 - 4000", "Above 400"))) -> 1000 - 2000 | D5: 2499 | E5: =D5-B5 -> 919 | F5: 0.37 | G5: 4.7 | H5: 7 | I5: =IF(G5<3,"Poor", IF(G5>=4.5,"Excelent","Average")) -> Excelent | J5: {=_xlfn.IFS(F5<=0.2,"Low Discount",F5<=0.4,"Medium Discount",F5>0.4,"High Discount")} -> Medium Discount
A6: Portable Home Small Air Humidifier 3-Speed Fan - Green | B6: 1740 | C6: =IF(B6<=1000, "0 - 1000", IF(B6 <=2000,"1000 - 2000", IF(B6<=4000,"2000 - 4000", "Above 400"))) -> 1000 - 2000 | D6: 2356 | E6: =D6-B6 -> 616 | F6: 0.26 | G6: 4.8 | H6: 5 | I6: =IF(G6<3,"Poor", IF(G6>=4.5,"Excelent","Average")) -> Excelent | J6: {=_xlfn.IFS(F6<=0.2,"Low Discount",F6<=0.4,"Medium Discount",F6>0.4,"High Discount")} -> Medium Discount
A7: 220V 60W Electric Soldering Iron Kits With Tools, Tips, And Multimeter | B7: 2999 | C7: =IF(B7<=1000, "0 - 1000", IF(B7 <=2000,"1000 - 2000", IF(B7<=4000,"2000 - 4000", "Above 400"))) -> 2000 - 4000 | D7: 3290 | E7: =D7-B7 -> 291 | F7: 0.09 | G7: 4 | H7: 15 | I7: =IF(G7<3,"Poor", IF(G7>=4.5,"Excelent","Average")) -> Average | J7: {=_xlfn.IFS(F7<=0.2,"Low Discount",F7<=0.4,"Medium Discount",F7>0.4,"High Discount")} -> Low Discount
A8: 137 Pieces Cake Decorating Tool Set Baking Supplies | B8: 2319 | C8: =IF(B8<=1000, "0 - 1000", IF(B8 <=2000,"1000 - 2000", IF(B8<=4000,"2000 - 4000", "Above 400"))) -> 2000 - 4000 | D8: 3032 | E8: =D8-B8 -> 713 | F8: 0.24 | G8: 4.6 | H8: 55 | I8: =IF(G8<3,"Poor", IF(G8>=4.5,"Excelent","Average")) -> Excelent | J8: {=_xlfn.IFS(F8<=0.2,"Low Discount",F8<=0.4,"Medium Discount",F8>0.4,"High Discount")} -> Medium Discount
A9: Desk Foldable Fan Adjustable Fan Strong Wind 3 Gear Usb | B9: 988 | C9: =IF(B9<=1000, "0 - 1000", IF(B9 <=2000,"1000 - 2000", IF(B9<=4000,"2000 - 4000", "Above 400"))) -> 0 - 1000 | D9: 1580 | E9: =D9-B9 -> 592 | F9: 0.37 | G9: 4 | H9: 2 | I9: =IF(G9<3,"Poor", IF(G9>=4.5,"Excelent","Average")) -> Average | J9: {=_xlfn.IFS(F9<=0.2,"Low Discount",F9<=0.4,"Medium Discount",F9>0.4,"High Discount")} -> Medium Discount
A10: LASA FOLDING TABLE SERVING STAND | B10: 1274 | C10: =IF(B10<=1000, "0 - 1000", IF(B10 <=2000,"1000 - 2000", IF(B10<=4000,"2000 - 4000", "Above 400"))) -> 1000 - 2000 | D10: 2800 | E10: =D10-B10 -> 1526 | F10: 0.55 | G10: 4.8 | H10: 5 | I10: =IF(G10<3,"Poor", IF(G10>=4.5,"Excelent","Average")) -> Excelent | J10: {=_xlfn.IFS(F10<=0.2,"Low Discount",F10<=0.4,"Medium Discount",F10>0.4,"High Discount")} -> High Discount
A11: 13 In 1 Home Repair Tools Box Kit Set | B11: 1600 | C11: =IF(B11<=1000, "0 - 1000", IF(B11 <=2000,"1000 - 2000", IF(B11<=4000,"2000 - 4000", "Above 400"))) -> 1000 - 2000 | D11: 2929 | E11: =D11-B11 -> 1329 | F11: 0.45 | G11: 3.8 | H11: 5 | I11: =IF(G11<3,"Poor", IF(G11>=4.5,"Excelent","Average")) -> Average | J11: {=_xlfn.IFS(F11<=0.2,"Low Discount",F11<=0.4,"Medium Discount",F11>0.4,"High Discount")} -> High Discount
A12: Genebre 115 In 1 Screwdriver Repairing Tool Set For IPhone Cellphone Hand Tool | B12: 799 | C12: =IF(B12<=1000, "0 - 1000", IF(B12 <=2000,"1000 - 2000", IF(B12<=4000,"2000 - 4000", "Above 400"))) -> 0 - 1000 | D12: 999 | E12: =D12-B12 -> 200 | F12: 0.2 | G12: 4.1 | H12: 12 | I12: =IF(G12<3,"Poor", IF(G12>=4.5,"Excelent","Average")) -> Average | J12: {=_xlfn.IFS(F12<=0.2,"Low Discount",F12<=0.4,"Medium Discount",F12>0.4,"High Discount")} -> Low Discount
A13: 100 Pcs Crochet Hook Tool Set Knitting Hook Set With Box | B13: 990 | C13: =IF(B13<=1000, "0 - 1000", IF(B13 <=2000,"1000 - 2000", IF(B13<=4000,"2000 - 4000", "Above 400"))) -> 0 - 1000 | D13: 1500 | E13: =D13-B13 -> 510 | F13: 0.34 | G13: 4.7 | H13: 39 | I13: =IF(G13<3,"Poor", IF(G13>=4.5,"Excelent","Average")) -> Excelent | J13: {=_xlfn.IFS(F13<=0.2,"Low Discount",F13<=0.4,"Medium Discount",F13>0.4,"High Discount")} -> Medium Discount
... A22: 3PCS Single Head Knitting Crochet Sweater Needle Set | B22: 38 | C22: =IF(B22<=1000, "0 - 1000", IF(B22 <=2000,"1000 - 2000", IF(B22<=4000,"2000 - 4000", "Above 400"))) -> 0 - 1000 | D22: 80 | E22: =D22-B22 -> 42 | F22: 0.53 | G22: 3.3 | H22: 13 | I22: =IF(G22<3,"Poor", IF(G22>=4.5,"Excelent","Average")) -> Average | J22: {=_xlfn.IFS(F22<=0.2,"Low Discount",F22<=0.4,"Medium Discount",F22>0.4,"High Discount")} -> High Discount
A23: 4pcs Bathroom/Kitchen Towel Rack,Roll Paper Holder,Towel Bars,Hook | B23: 1860 | C23: =IF(B23<=1000, "0 - 1000", IF(B23 <=2000,"1000 - 2000", IF(B23<=4000,"2000 - 4000", "Above 400"))) -> 1000 - 2000 | D23: 3220 | E23: =D23-B23 -> 1360 | F23: 0.42 | I23: =IF(G23<3,"Poor", IF(G23>=4.5,"Excelent","Average")) -> Poor | J23: {=_xlfn.IFS(F23<=0.2,"Low Discount",F23<=0.4,"Medium Discount",F23>0.4,"High Discount")} -> High Discount
A24: LED Romantic Spaceship Starry Sky Projector,Children's Bedroom Night Light-Blue | B24: 880 | C24: =IF(B24<=1000, "0 - 1000", IF(B24 <=2000,"1000 - 2000", IF(B24<=4000,"2000 - 4000", "Above 400"))) -> 0 - 1000 | D24: 1350 | E24: =D24-B24 -> 470 | F24: 0.35 | G24: 4 | H24: 6 | I24: =IF(G24<3,"Poor", IF(G24>=4.5,"Excelent","Average")) -> Average | J24: {=_xlfn.IFS(F24<=0.2,"Low Discount",F24<=0.4,"Medium Discount",F24>0.4,"High Discount")} -> Medium Discount
A25: Foldable Overbed Table/Desk | B25: 1650 | C25: =IF(B25<=1000, "0 - 1000", IF(B25 <=2000,"1000 - 2000", IF(B25<=4000,"2000 - 4000", "Above 400"))) -> 1000 - 2000 | D25: 2150 | E25: =D25-B25 -> 500 | F25: 0.23 | G25: 4.4 | H25: 14 | I25: =IF(G25<3,"Poor", IF(G25>=4.5,"Excelent","Average")) -> Average | J25: {=_xlfn.IFS(F25<=0.2,"Low Discount",F25<=0.4,"Medium Discount",F25>0.4,"High Discount")} -> Medium Discount
A26: LASA 3 Tier Bamboo Shoe Bench Storage Shelf | B26: 2048 | C26: =IF(B26<=1000, "0 - 1000", IF(B26 <=2000,"1000 - 2000", IF(B26<=4000,"2000 - 4000", "Above 400"))) -> 2000 - 4000 | D26: 4500 | E26: =D26-B26 -> 2452 | F26: 0.54 | G26: 4.3 | H26: 7 | I26: =IF(G26<3,"Poor", IF(G26>=4.5,"Excelent","Average")) -> Average | J26: {=_xlfn.IFS(F26<=0.2,"Low Discount",F26<=0.4,"Medium Discount",F26>0.4,"High Discount")} -> High Discount
A27: Electronic Digital Display Vernier Caliper | B27: 420 | C27: =IF(B27<=1000, "0 - 1000", IF(B27 <=2000,"1000 - 2000", IF(B27<=4000,"2000 - 4000", "Above 400"))) -> 0 - 1000 | D27: 647 | E27: =D27-B27 -> 227 | F27: 0.35 | G27: 4.6 | H27: 49 | I27: =IF(G27<3,"Poor", IF(G27>=4.5,"Excelent","Average")) -> Excelent | J27: {=_xlfn.IFS(F27<=0.2,"Low Discount",F27<=0.4,"Medium Discount",F27>0.4,"High Discount")} -> Medium Discount
A28: Portable Wardrobe Nonwoven With 3 Hanging Rods And 6 Storage Shelves | B28: 2880 | C28: =IF(B28<=1000, "0 - 1000", IF(B28 <=2000,"1000 - 2000", IF(B28<=4000,"2000 - 4000", "Above 400"))) -> 2000 - 4000 | D28: 3520 | E28: =D28-B28 -> 640 | F28: 0.18 | G28: 3.8 | H28: 12 | I28: =IF(G28<3,"Poor", IF(G28>=4.5,"Excelent","Average")) -> Average | J28: {=_xlfn.IFS(F28<=0.2,"Low Discount",F28<=0.4,"Medium Discount",F28>0.4,"High Discount")} -> Low Discount
A29: 12 Litre Black Insulated Lunch Box | B29: 1350 | C29: =IF(B29<=1000, "0 - 1000", IF(B29 <=2000,"1000 - 2000", IF(B29<=4000,"2000 - 4000", "Above 400"))) -> 1000 - 2000 | D29: 1990 | E29: =D29-B29 -> 640 | F29: 0.32 | G29: 3.8 | H29: 13 | I29: =IF(G29<3,"Poor", IF(G29>=4.5,"Excelent","Average")) -> Average | J29: {=_xlfn.IFS(F29<=0.2,"Low Discount",F29<=0.4,"Medium Discount",F29>0.4,"High Discount")} -> Medium Discount
A30: 52 Pieces Cake Decorating Tool Set Gift Kit Baking Supplies | B30: 1758 | C30: =IF(B30<=1000, "0 - 1000", IF(B30 <=2000,"1000 - 2000", IF(B30<=4000,"2000 - 4000", "Above 400"))) -> 1000 - 2000 | D30: 2499 | E30: =D30-B30 -> 741 | F30: 0.3 | G30: 4.1 | H30: 20 | I30: =IF(G30<3,"Poor", IF(G30>=4.5,"Excelent","Average")) -> Average | J30: {=_xlfn.IFS(F30<=0.2,"Low Discount",F30<=0.4,"Medium Discount",F30>0.4,"High Discount")} -> Medium Discount
A31: MultiFunctional Storage Rack Multi-layer Bookshelf | B31: 2200 | C31: =IF(B31<=1000, "0 - 1000", IF(B31 <=2000,"1000 - 2000", IF(B31<=4000,"2000 - 4000", "Above 400"))) -> 2000 - 4000 | D31: 4080 | E31: =D31-B31 -> 1880 | F31: 0.46 | I31: =IF(G31<3,"Poor", IF(G31>=4.5,"Excelent","Average")) -> Poor | J31: {=_xlfn.IFS(F31<=0.2,"Low Discount",F31<=0.4,"Medium Discount",F31>0.4,"High Discount")} -> High Discount
A32: Exfoliate And Exfoliate Face Towel - Black | B32: 185 | C32: =IF(B32<=1000, "0 - 1000", IF(B32 <=2000,"1000 - 2000", IF(B32<=4000,"2000 - 4000", "Above 400"))) -> 0 - 1000 | D32: 382 | E32: =D32-B32 -> 197 | F32: 0.52 | G32: 4.3 | H32: 9 | I32: =IF(G32<3,"Poor", IF(G32>=4.5,"Excelent","Average")) -> Average | J32: {=_xlfn.IFS(F32<=0.2,"Low Discount",F32<=0.4,"Medium Discount",F32>0.4,"High Discount")} -> High Discount
A33: 12 Litre Insulated Lunch Box Grey | B33: 980 | C33: =IF(B33<=1000, "0 - 1000", IF(B33 <=2000,"1000 - 2000", IF(B33<=4000,"2000 - 4000", "Above 400"))) -> 0 - 1000 | D33: 1490 | E33: =D33-B33 -> 510 | F33: 0.34 | G33: 4.7 | H33: 12 | I33: =IF(G33<3,"Poor", IF(G33>=4.5,"Excelent","Average")) -> Excelent | J33: {=_xlfn.IFS(F33<=0.2,"Low Discount",F33<=0.4,"Medium Discount",F33>0.4,"High Discount")} -> Medium Discount
A34: LED Eye Protection Desk Lamp , Study, Reading, USB Fan - Double Pen Holder | B34: 1820 | C34: =IF(B34<=1000, "0 - 1000", IF(B34 <=2000,"1000 - 2000", IF(B34<=4000,"2000 - 4000", "Above 400"))) -> 1000 - 2000 | D34: 3490 | E34: =D34-B34 -> 1670 | F34: 0.48 | G34: 4.3 | H34: 9 | I34: =IF(G34<3,"Poor", IF(G34>=4.5,"Excelent","Average")) -> Average | J34: {=_xlfn.IFS(F34<=0.2,"Low Discount",F34<=0.4,"Medium Discount",F34>0.4,"High Discount")} -> High Discount
A35: 53Pcs/Set Yarn Knitting Crochet Hooks With Bag - Fortune Cat | B35: 1940 | C35: =IF(B35<=1000, "0 - 1000", IF(B35 <=2000,"1000 - 2000", IF(B35<=4000,"2000 - 4000", "Above 400"))) -> 1000 - 2000 | D35: 2650 | E35: =D35-B35 -> 710 | F35: 0.27 | G35: 4.7 | H35: 20 | I35: =IF(G35<3,"Poor", IF(G35>=4.5,"Excelent","Average")) -> Excelent | J35: {=_xlfn.IFS(F35<=0.2,"Low Discount",F35<=0.4,"Medium Discount",F35>0.4,"High Discount")} -> Medium Discount
A36: 53 Pieces/Set Yarn Knitting Crochet Hooks With Bag - Pansies | B36: 1980 | C36: =IF(B36<=1000, "0 - 1000", IF(B36 <=2000,"1000 - 2000", IF(B36<=4000,"2000 - 4000", "Above 400"))) -> 1000 - 2000 | D36: 2699 | E36: =D36-B36 -> 719 | F36: 0.27 | G36: 4.5 | H36: 32 | I36: =IF(G36<3,"Poor", IF(G36>=4.5,"Excelent","Average")) -> Excelent | J36: {=_xlfn.IFS(F36<=0.2,"Low Discount",F36<=0.4,"Medium Discount",F36>0.4,"High Discount")} -> Medium Discount
A37: DIY File Folder, Office Drawer File Holder, Pen Holder, Desktop Storage Rack | B37: 1620 | C37: =IF(B37<=1000, "0 - 1000", IF(B37 <=2000,"1000 - 2000", IF(B37<=4000,"2000 - 4000", "Above 400"))) -> 1000 - 2000 | D37: 2690 | E37: =D37-B37 -> 1070 | F37: 0.4 | G37: 5 | H37: 1 | I37: =IF(G37<3,"Poor", IF(G37>=4.5,"Excelent","Average")) -> Excelent | J37: {=_xlfn.IFS(F37<=0.2,"Low Discount",F37<=0.4,"Medium Discount",F37>0.4,"High Discount")} -> Medium Discount
A38: Classic Black Cat Cotton Hemp Pillow Case For Home Car | B38: 171 | C38: =IF(B38<=1000, "0 - 1000", IF(B38 <=2000,"1000 - 2000", IF(B38<=4000,"2000 - 4000", "Above 400"))) -> 0 - 1000 | D38: 360 | E38: =D38-B38 -> 189 | F38: 0.53 | G38: 5 | H38: 2 | I38: =IF(G38<3,"Poor", IF(G38>=4.5,"Excelent","Average")) -> Excelent | J38: {=_xlfn.IFS(F38<=0.2,"Low Discount",F38<=0.4,"Medium Discount",F38>0.4,"High Discount")} -> High Discount
A39: Punch-free Great Load Bearing Bathroom Storage Rack Wall Shelf-White | B39: 389 | C39: =IF(B39<=1000, "0 - 1000", IF(B39 <=2000,"1000 - 2000", IF(B39<=4000,"2000 - 4000", "Above 400"))) -> 0 - 1000 | D39: 656 | E39: =D39-B39 -> 267 | F39: 0.41 | G39: 4.3 | H39: 36 | I39: =IF(G39<3,"Poor", IF(G39>=4.5,"Excelent","Average")) -> Average | J39: {=_xlfn.IFS(F39<=0.2,"Low Discount",F39<=0.4,"Medium Discount",F39>0.4,"High Discount")} -> High Discount
A40: LASA Stainless Steel Double Wall Mount Soap Dispenser - 500ml | B40: 2750 | C40: =IF(B40<=1000, "0 - 1000", IF(B40 <=2000,"1000 - 2000", IF(B40<=4000,"2000 - 4000", "Above 400"))) -> 2000 - 4000 | D40: 4471 | E40: =D40-B40 -> 1721 | F40: 0.38 | I40: =IF(G40<3,"Poor", IF(G40>=4.5,"Excelent","Average")) -> Poor | J40: {=_xlfn.IFS(F40<=0.2,"Low Discount",F40<=0.4,"Medium Discount",F40>0.4,"High Discount")} -> Medium Discount
A41: 4M Float Switch Water Level Controller -Water Tank | B41: 475 | C41: =IF(B41<=1000, "0 - 1000", IF(B41 <=2000,"1000 - 2000", IF(B41<=4000,"2000 - 4000", "Above 400"))) -> 0 - 1000 | D41: 931 | E41: =D41-B41 -> 456 | F41: 0.49 | I41: =IF(G41<3,"Poor", IF(G41>=4.5,"Excelent","Average")) -> Poor | J41: {=_xlfn.IFS(F41<=0.2,"Low Discount",F41<=0.4,"Medium Discount",F41>0.4,"High Discount")} -> High Discount
A42: Modern Sofa Throw Pillow Cover-45x45cm-Blue&Red | B42: 238 | C42: =IF(B42<=1000, "0 - 1000", IF(B42 <=2000,"1000 - 2000", IF(B42<=4000,"2000 - 4000", "Above 400"))) -> 0 - 1000 | D42: 476 | E42: =D42-B42 -> 238 | F42: 0.5 | I42: =IF(G42<3,"Poor", IF(G42>=4.5,"Excelent","Average")) -> Poor | J42: {=_xlfn.IFS(F42<=0.2,"Low Discount",F42<=0.4,"Medium Discount",F42>0.4,"High Discount")} -> High Discount
A43: Balloon Insert, Birthday Party Balloon Set, PU Leather | B43: 610 | C43: =IF(B43<=1000, "0 - 1000", IF(B43 <=2000,"1000 - 2000", IF(B43<=4000,"2000 - 4000", "Above 400"))) -> 0 - 1000 | D43: 1060 | E43: =D43-B43 -> 450 | F43: 0.42 | I43: =IF(G43<3,"Poor", IF(G43>=4.5,"Excelent","Average")) -> Poor | J43: {=_xlfn.IFS(F43<=0.2,"Low Discount",F43<=0.4,"Medium Discount",F43>0.4,"High Discount")} -> High Discount
A44: Shower Cap Wide Elastic Band Cover Reusable Bashroom Cap | B44: 2132 | C44: =IF(B44<=1000, "0 - 1000", IF(B44 <=2000,"1000 - 2000", IF(B44<=4000,"2000 - 4000", "Above 400"))) -> 2000 - 4000 | D44: 2169 | E44: =D44-B44 -> 37 | F44: 0.02 | I44: =IF(G44<3,"Poor", IF(G44>=4.5,"Excelent","Average")) -> Poor | J44: {=_xlfn.IFS(F44<=0.2,"Low Discount",F44<=0.4,"Medium Discount",F44>0.4,"High Discount")} -> Low Discount
A45: Christmas Elk Fence Yard Lawn Decorations Cute For Holidays | B45: 999 | C45: =IF(B45<=1000, "0 - 1000", IF(B45 <=2000,"1000 - 2000", IF(B45<=4000,"2000 - 4000", "Above 400"))) -> 0 - 1000 | D45: 2000 | E45: =D45-B45 -> 1001 | F45: 0.5 | I45: =IF(G45<3,"Poor", IF(G45>=4.5,"Excelent","Average")) -> Poor | J45: {=_xlfn.IFS(F45<=0.2,"Low Discount",F45<=0.4,"Medium Discount",F45>0.4,"High Discount")} -> High Discount
A46: 60W Hot Melt Glue Sprayer - Efficient And Stable Glue Dispensing | B46: 1190 | C46: =IF(B46<=1000, "0 - 1000", IF(B46 <=2000,"1000 - 2000", IF(B46<=4000,"2000 - 4000", "Above 400"))) -> 1000 - 2000 | D46: 1785 | E46: =D46-B46 -> 595 | F46: 0.33 | I46: =IF(G46<3,"Poor", IF(G46>=4.5,"Excelent","Average")) -> Poor | J46: {=_xlfn.IFS(F46<=0.2,"Low Discount",F46<=0.4,"Medium Discount",F46>0.4,"High Discount")} -> Medium Discount
A47: Car Phone Charging Stand | B47: 671 | C47: =IF(B47<=1000, "0 - 1000", IF(B47 <=2000,"1000 - 2000", IF(B47<=4000,"2000 - 4000", "Above 400"))) -> 0 - 1000 | D47: 1316 | E47: =D47-B47 -> 645 | F47: 0.49 | I47: =IF(G47<3,"Poor", IF(G47>=4.5,"Excelent","Average")) -> Poor | J47: {=_xlfn.IFS(F47<=0.2,"Low Discount",F47<=0.4,"Medium Discount",F47>0.4,"High Discount")} -> High Discount
A48: 2pcs Solar Street Light Flood Light Outdoor | B48: 1200 | C48: =IF(B48<=1000, "0 - 1000", IF(B48 <=2000,"1000 - 2000", IF(B48<=4000,"2000 - 4000", "Above 400"))) -> 1000 - 2000 | D48: 1950 | E48: =D48-B48 -> 750 | F48: 0.38 | I48: =IF(G48<3,"Poor", IF(G48>=4.5,"Excelent","Average")) -> Poor | J48: {=_xlfn.IFS(F48<=0.2,"Low Discount",F48<=0.4,"Medium Discount",F48>0.4,"High Discount")} -> Medium Discount
...

Sheet Descriptive Analysis
B2: Values
B3: Average of Discount | C3: 0.3637037
B4: Average of Current price | C4: 1202.7778
B5: Average of Old Price | C5: 1829.7685
B6: Average of Ratings | C6: 3.8785714
B10: Row Labels | C10: Average of Ratings | D10: Average of Discount
B11: High Discount | C11: 3.6133333 | D11: 0.4820339
B12: Low Discount | C12: 3.8 | D12: 0.078947368
B13: Medium Discount | C13: 4.2761905 | D13: 0.31133333
B14: Grand Total | C14: 3.8785714 | D14: 0.3637037
B18: Row Labels | C18: Count of Product
B19: Average | C19: 22
B20: Excelent | C20: 22
B21: Poor | C21: 64
B22: Grand Total | C22: 108

Sheet Trend and Relationship Analysis

Sheet Scattered Helper Discount
C3: Product | D3: Max of Discount | E3: Max of Review
C4: 100 Pcs Crochet Hook Tool Set Knitting Hook Set With Box | D4: 0.34 | E4: 39
C5: 115 Piece Set Of Multifunctional Precision Screwdrivers | D5: 0.38 | E5: 2
C6: 12 Litre Black Insulated Lunch Box | D6: 0.32 | E6: 13
C7: 12 Litre Insulated Lunch Box Grey | D7: 0.34 | E7: 12
C8: 120W Cordless Vacuum Cleaners Handheld Electric Vacuum Cleaner | D8: 0.49 | E8: 69
C9: 12V 19500rpm Handheld Electric Angle Grinder Tool - UK - Yellow/Black | D9: 0.27
C10: 13 In 1 Home Repair Tools Box Kit Set | D10: 0.45 | E10: 5
C11: 137 Pieces Cake Decorating Tool Set Baking Supplies | D11: 0.24 | E11: 55
C12: 1PC Refrigerator Food Seal Pocket Fridge Bags | D12: 0.24
C13: 2 Pairs Cowhide Split Leather Work Gloves.32â„‰ Or Above Welding Gloves | D13: 0.02
C14: 220V 60W Electric Soldering Iron Kits With Tools, Tips, And Multimeter | D14: 0.09 | E14: 15
C15: 24 Grid Wall-mounted Sundries Organiser Fabric Closet Bag Storage Rack | D15: 0.01
C16: 2PCS Ice Silk Square Cushion Cover Pillowcases - 65x65cm | D16: 0.5
C17: 2pcs Solar Street Light Flood Light Outdoor | D17: 0.38
C18: 2PCS/LOT Solar LED Outdoor Intelligent Light Controlled Wall Lamp | D18: 0.47
C19: 32PCS Portable Cordless Drill Set With Cyclic Battery Drive -26 Variable Speed | D19: 0.39 | E19: 5
C20: 380ML USB Rechargeable Portable Small Blenders And Juicers | D20: 0.5 | E20: 7
C21: 3D Waterproof EVA Plastic Shower Curtain 1.8*2Mtrs | D21: 0.49 | E21: 44
C22: 3PCS Rotary Scraper Thermomix For Kitchen | D22: 0.43
C23: 3PCS Single Head Knitting Crochet Sweater Needle Set | D23: 0.53 | E23: 13
C24: 4 Piece Coloured Stainless Steel Kitchenware Set | D24: 0.49
C25: 40cm Gold DIY Acrylic Wall Sticker Clock | D25: 0.47 | E25: 12
C26: 4M Float Switch Water Level Controller -Water Tank | D26: 0.49
C27: 4pcs Bathroom/Kitchen Towel Rack,Roll Paper Holder,Towel Bars,Hook | D27: 0.42
C28: 5 Pieces/set Of Stainless Steel Induction Cooker Pots | D28: 0.13 | E28: 6
C29: 52 Pieces Cake Decorating Tool Set Gift Kit Baking Supplies | D29: 0.3 | E29: 20
C30: 53 Pieces/Set Yarn Knitting Crochet Hooks With Bag - Pansies | D30: 0.27 | E30: 32
C31: 53Pcs/Set Yarn Knitting Crochet Hooks With Bag - Fortune Cat | D31: 0.27 | E31: 20
C32: 5m Waterproof Spherical LED String Lights Outdoor Ball Chain Lights Party Lighting Decoration Adjustable | D32: 0.36
C33: 5-PCS Stainless Steel Cooking Pot Set With Steamed Slices | D33: 0.55 | E33: 13
C34: 6 In 1 Bottle Can Opener Multifunctional Easy Opener | D34: 0.64
C35: 6 Layers Steel Pipe Assembling Dustproof Storage Shoe Cabinet | D35: 0.47
C36: 60W Hot Melt Glue Sprayer - Efficient And Stable Glue Dispensing | D36: 0.33
C37: 7PCS Silicone Thumb Knife Finger Protector Vegetable Harvesting Knife | D37: 0.49
C38: 7-piece Set Of Storage Bags, Travel Storage Bags, Shoe Bags | D38: 0.47 | E38: 6
C39: 8in1 Screwdriver With LED Light | D39: 0.42
C40: 9pcs Gas Mask, For Painting, Dust, Formaldehyde Grinding, Polishing | D40: 0.41
C41: Agapeon Toothbrush Holder And Toothpaste Dispenser | D41: 0.45 | E41: 17
C42: Angle Measuring Tool Full Metal Multi Angle Measuring Tool | D42: 0.49
...

Sheet Scattered Plot Ratings
D4: Product | E4: Max of Ratings | F4: Max of Review
D5: 100 Pcs Crochet Hook Tool Set Knitting Hook Set With Box | E5: 4.7 | F5: 39
D6: 115 Piece Set Of Multifunctional Precision Screwdrivers | E6: 4.5 | F6: 2
D7: 12 Litre Black Insulated Lunch Box | E7: 3.8 | F7: 13
D8: 12 Litre Insulated Lunch Box Grey | E8: 4.7 | F8: 12
D9: 120W Cordless Vacuum Cleaners Handheld Electric Vacuum Cleaner | E9: 2.8 | F9: 69
D10: 12V 19500rpm Handheld Electric Angle Grinder Tool - UK - Yellow/Black
D11: 13 In 1 Home Repair Tools Box Kit Set | E11: 3.8 | F11: 5
D12: 137 Pieces Cake Decorating Tool Set Baking Supplies | E12: 4.6 | F12: 55
D13: 1PC Refrigerator Food Seal Pocket Fridge Bags
D14: 2 Pairs Cowhide Split Leather Work Gloves.32â„‰ Or Above Welding Gloves
D15: 220V 60W Electric Soldering Iron Kits With Tools, Tips, And Multimeter | E15: 4 | F15: 15
D16: 24 Grid Wall-mounted Sundries Organiser Fabric Closet Bag Storage Rack
D17: 2PCS Ice Silk Square Cushion Cover Pillowcases - 65x65cm
D18: 2pcs Solar Street Light Flood Light Outdoor
D19: 2PCS/LOT Solar LED Outdoor Intelligent Light Controlled Wall Lamp
D20: 32PCS Portable Cordless Drill Set With Cyclic Battery Drive -26 Variable Speed | E20: 3 | F20: 5
D21: 380ML USB Rechargeable Portable Small Blenders And Juicers | E21: 2.3 | F21: 7
D22: 3D Waterproof EVA Plastic Shower Curtain 1.8*2Mtrs | E22: 4.6 | F22: 44
D23: 3PCS Rotary Scraper Thermomix For Kitchen
D24: 3PCS Single Head Knitting Crochet Sweater Needle Set | E24: 3.3 | F24: 13
D25: 4 Piece Coloured Stainless Steel Kitchenware Set
D26: 40cm Gold DIY Acrylic Wall Sticker Clock | E26: 4.8 | F26: 12
D27: 4M Float Switch Water Level Controller -Water Tank
D28: 4pcs Bathroom/Kitchen Towel Rack,Roll Paper Holder,Towel Bars,Hook
D29: 5 Pieces/set Of Stainless Steel Induction Cooker Pots | E29: 2.5 | F29: 6
D30: 52 Pieces Cake Decorating Tool Set Gift Kit Baking Supplies | E30: 4.1 | F30: 20
D31: 53 Pieces/Set Yarn Knitting Crochet Hooks With Bag - Pansies | E31: 4.5 | F31: 32
D32: 53Pcs/Set Yarn Knitting Crochet Hooks With Bag - Fortune Cat | E32: 4.7 | F32: 20
D33: 5m Waterproof Spherical LED String Lights Outdoor Ball Chain Lights Party Lighting Decoration Adjustable
D34: 5-PCS Stainless Steel Cooking Pot Set With Steamed Slices | E34: 2.1 | F34: 13
D35: 6 In 1 Bottle Can Opener Multifunctional Easy Opener
D36: 6 Layers Steel Pipe Assembling Dustproof Storage Shoe Cabinet
D37: 60W Hot Melt Glue Sprayer - Efficient And Stable Glue Dispensing
D38: 7PCS Silicone Thumb Knife Finger Protector Vegetable Harvesting Knife
D39: 7-piece Set Of Storage Bags, Travel Storage Bags, Shoe Bags | E39: 2.2 | F39: 6
D40: 8in1 Screwdriver With LED Light
D41: 9pcs Gas Mask, For Painting, Dust, Formaldehyde Grinding, Polishing
D42: Agapeon Toothbrush Holder And Toothpaste Dispenser | E42: 2.6 | F42: 17
D43: Angle Measuring Tool Full Metal Multi Angle Measuring Tool
...

Sheet Product perfomance
C3: Product | D3: Max of Discount
C4: Mythco 120COB Solar Wall Ligt With Motion Sensor And Remote Control 3 Modes | D4: 0.54
C5: LASA FOLDING TABLE SERVING STAND | D5: 0.55
C6: LASA 3 Tier Bamboo Shoe Bench Storage Shelf | D6: 0.54
C7: Intelligent LED Body Sensor Wireless Lighting Night Light USB | D7: 0.52
C8: Exfoliate And Exfoliate Face Towel - Black | D8: 0.52
C9: Creative Owl Shape Keychain Black | D9: 0.61
C10: Classic Black Cat Cotton Hemp Pillow Case For Home Car | D10: 0.53
C11: 6 In 1 Bottle Can Opener Multifunctional Easy Opener | D11: 0.64
C12: 5-PCS Stainless Steel Cooking Pot Set With Steamed Slices | D12: 0.55
C13: 3PCS Single Head Knitting Crochet Sweater Needle Set | D13: 0.53
C14: Grand Total | D14: 0.64
C35: Row Labels | D35: Max of Review
C36: 100 Pcs Crochet Hook Tool Set Knitting Hook Set With Box | D36: 39
C37: 120W Cordless Vacuum Cleaners Handheld Electric Vacuum Cleaner | D37: 69
C38: 137 Pieces Cake Decorating Tool Set Baking Supplies | D38: 55
C39: 3D Waterproof EVA Plastic Shower Curtain 1.8*2Mtrs | D39: 44
C40: 52 Pieces Cake Decorating Tool Set Gift Kit Baking Supplies | D40: 20
C41: 53 Pieces/Set Yarn Knitting Crochet Hooks With Bag - Pansies | D41: 32
C42: 53Pcs/Set Yarn Knitting Crochet Hooks With Bag - Fortune Cat | D42: 20
C43: Electronic Digital Display Vernier Caliper | D43: 49
C44: Portable Mini Cordless Car Vacuum Cleaner - Blue | D44: 24
C45: Punch-free Great Load Bearing Bathroom Storage Rack Wall Shelf-White | D45: 36
C46: Grand Total | D46: 69

Sheet Top 5 Highest
C4: Row Labels | D4: Max of Ratings
C5: Anti-Skid Absorbent Insulation Coaster For Home Office | D5: 5
C6: Bedroom Simple Floor Hanging Clothes Rack Single Pole Hat Rack - White | D6: 5
C7: Classic Black Cat Cotton Hemp Pillow Case For Home Car | D7: 5
C8: DIY File Folder, Office Drawer File Holder, Pen Holder, Desktop Storage Rack | D8: 5
C9: Konka Healty Electric Kettle, 24-hour Heat Preservation,1.5L,800W, White | D9: 5
C10: LASA Aluminum Folding Truck Hand Cart - 68kg Max | D10: 5
C11: Peacock Throw Pillow Cushion Case For Home Car | D11: 5
C12: Grand Total | D12: 5

Sheet Range slicer
C3: Row Labels | D3: Average of Ratings | E3: Count of Review
C4: High Discount | D4: 3.6133333 | E4: 30
C5: Low Discount | D5: 3.8 | E5: 5
C6: Medium Discount | D6: 4.2761905 | E6: 21
C7: Grand Total | D7: 3.8785714 | E7: 56
E33: Row Labels | F33: Count of Product
E34: 0 - 1000 | F34: 55
E35: 1000 - 2000 | F35: 36
E36: 2000 - 4000 | F36: 17
E37: Grand Total | F37: 108

Sheet DASHBOARD
AM39: Discount | AN39: Review | AU39: Ratings | AV39: Review
AM40: ='Scattered Helper Discount'!D4 -> 0.34 | AN40: ='Scattered Helper Discount'!E4 -> 39 | AU40: ='Scattered Plot Ratings'!E5 -> 4.7 | AV40: ='Scattered Plot Ratings'!F5 -> 39
AM41: ='Scattered Helper Discount'!D5 -> 0.38 | AN41: ='Scattered Helper Discount'!E5 -> 2 | AU41: ='Scattered Plot Ratings'!E6 -> 4.5 | AV41: ='Scattered Plot Ratings'!F6 -> 2
AM42: ='Scattered Helper Discount'!D6 -> 0.32 | AN42: ='Scattered Helper Discount'!E6 -> 13 | AU42: ='Scattered Plot Ratings'!E7 -> 3.8 | AV42: ='Scattered Plot Ratings'!F7 -> 13
AM43: ='Scattered Helper Discount'!D7 -> 0.34 | AN43: ='Scattered Helper Discount'!E7 -> 12 | AU43: ='Scattered Plot Ratings'!E8 -> 4.7 | AV43: ='Scattered Plot Ratings'!F8 -> 12
AM44: ='Scattered Helper Discount'!D8 -> 0.49 | AN44: ='Scattered Helper Discount'!E8 -> 69 | AU44: ='Scattered Plot Ratings'!E9 -> 2.8 | AV44: ='Scattered Plot Ratings'!F9 -> 69
AM45: ='Scattered Helper Discount'!D9 -> 0.27 | AN45: ='Scattered Helper Discount'!E9 -> 0 | AU45: ='Scattered Plot Ratings'!E10 -> 0 | AV45: ='Scattered Plot Ratings'!F10 -> 0
AM46: ='Scattered Helper Discount'!D10 -> 0.45 | AN46: ='Scattered Helper Discount'!E10 -> 5 | AU46: ='Scattered Plot Ratings'!E11 -> 3.8 | AV46: ='Scattered Plot Ratings'!F11 -> 5
AM47: ='Scattered Helper Discount'!D11 -> 0.24 | AN47: ='Scattered Helper Discount'!E11 -> 55 | AU47: ='Scattered Plot Ratings'!E12 -> 4.6 | AV47: ='Scattered Plot Ratings'!F12 -> 55
AM48: ='Scattered Helper Discount'!D12 -> 0.24 | AN48: ='Scattered Helper Discount'!E12 -> 0 | AU48: ='Scattered Plot Ratings'!E13 -> 0 | AV48: ='Scattered Plot Ratings'!F13 -> 0
AM49: ='Scattered Helper Discount'!D13 -> 0.02 | AN49: ='Scattered Helper Discount'!E13 -> 0 | AU49: ='Scattered Plot Ratings'!E14 -> 0 | AV49: ='Scattered Plot Ratings'!F14 -> 0
AM50: ='Scattered Helper Discount'!D14 -> 0.09 | AN50: ='Scattered Helper Discount'!E14 -> 15 | AU50: ='Scattered Plot Ratings'!E15 -> 4 | AV50: ='Scattered Plot Ratings'!F15 -> 15
AM51: ='Scattered Helper Discount'!D15 -> 0.01 | AN51: ='Scattered Helper Discount'!E15 -> 0 | AU51: ='Scattered Plot Ratings'!E16 -> 0 | AV51: ='Scattered Plot Ratings'!F16 -> 0
... AM147: ='Scattered Helper Discount'!D111 -> 0.43 | AN147: ='Scattered Helper Discount'!E111 -> 5 | AU147: ='Scattered Plot Ratings'!E112 -> 3 | AV147: ='Scattered Plot Ratings'!F112 -> 5
